Workbook

Sheet Teacher Salary Data
A1: District | B1: State | C1: Education Level | D1: Years Experience | E1: Salary | F1: Last Verified
A2: Alief ISD | B2: TX | C2: Bachelor's | D2: 0 | E2: 64100 | F2: 2026-06-10
A3: Alief ISD | B3: TX | C3: Bachelor's | D3: 1 | E3: 64350 | F3: 2026-06-10
A4: Alief ISD | B4: TX | C4: Bachelor's | D4: 2 | E4: 64600 | F4: 2026-06-10
A5: Alief ISD | B5: TX | C5: Bachelor's | D5: 3 | E5: 64850 | F5: 2026-06-10
A6: Alief ISD | B6: TX | C6: Bachelor's | D6: 4 | E6: 65100 | F6: 2026-06-10
A7: Alief ISD | B7: TX | C7: Bachelor's | D7: 5 | E7: 65350 | F7: 2026-06-10
A8: Alief ISD | B8: TX | C8: Bachelor's | D8: 6 | E8: 65600 | F8: 2026-06-10
A9: Alief ISD | B9: TX | C9: Bachelor's | D9: 7 | E9: 65850 | F9: 2026-06-10
A10: Alief ISD | B10: TX | C10: Bachelor's | D10: 8 | E10: 66100 | F10: 2026-06-10
A11: Alief ISD | B11: TX | C11: Bachelor's | D11: 9 | E11: 66350 | F11: 2026-06-10
A12: Alief ISD | B12: TX | C12: Bachelor's | D12: 10 | E12: 66600 | F12: 2026-06-10
A13: Alief ISD | B13: TX | C13: Master's | D13: 0 | E13: 64600 | F13: 2026-06-10
... A1387: West Des Moines Community Schools | B1387: IA | C1387: Master's | D1387: 10 | E1387: 65512 | F1387: 2026-06-13

Sheet School District Profiles
A1: District | B1: State | C1: Region | D1: White % | E1: Hispanic % | F1: Asian % | G1: Black % | H1: Student Teacher Ratio | I1: Daily Sub Pay | J1: Other % | K1: Number of High Schools | L1: Number of Middle Schools | M1: Number of Elementary Schools | N1: Other / Specialty Schools | O1: Total Schools Counted | P1: Source URL | Q1: Last Verified | R1: Other %
A2: Alief ISD | B2: TX | C2: Houston | D2: 3 | E2: 62 | F2: 10 | G2: 24 | H2: 13 | I2: 125 | J2: =100-SUM(D2:G2) | K2: 6 | L2: 12 | M2: 27 | N2: 1 | O2: 46
A3: Arcadia Unified School District | B3: CA | C3: Southern California | D3: 26 | E3: 10 | F3: 61 | G3: 1 | H3: 24.58 | I3: 200 | J3: =100-SUM(D3:G3) | K3: 1 | L3: 3 | M3: 6 | N3: 1 | O3: 11 | P3: AUSD reports six elementary schools, three middle schools, one comprehensive high school, and one alternative school/outreach program. Master's degree alone appears in the same Column 1 as BA on the ATA schedule, so BA and MA entries use the same column unless additional semester units are earned.
A4: Austin ISD | B4: TX | C4: Austin | D4: 30.68 | E4: 54.14 | F4: 4.84 | G4: 6.01 | H4: 13.7 | I4: 155 | J4: =100-SUM(D4:G4) | K4: 13 | L4: 19 | M4: 78 | N4: 4 | O4: 114 | P4: School-directory pages include a 6-12 campus (Ann Richards) in both the middle and high lists; counts below are normalized to the district's cited 114 schools and classify Ann Richards with middle schools.
A5: Barbers Hill ISD | B5: TX | C5: Houston | D5: 57.2 | E5: 32.1 | F5: 1.9 | G5: 4.8 | H5: 13 | I5: 135 | J5: =100-SUM(D5:G5) | K5: 1 | L5: 2 | M5: 5 | N5: 0 | O5: 8 | P5: District schools page lists one traditional high school (Barbers Hill High School), two middle school campuses, five elementary/early childhood campuses, and no separate alternative high school counted for this prototype.
A6: Canyons School District | B6: UT | C6: Salt Lake Valley | D6: 71 | E6: 18 | F6: 3 | G6: 2 | H6: 21.35 | I6: 180 | J6: =100-SUM(D6:G6) | K6: 6 | L6: 8 | M6: 28 | N6: 8 | O6: 50 | P6: NCES lists 50 total schools; counts follow district school directory categories with 8 specialty schools.
A7: Chandler Unified School District | B7: AZ | C7: Phoenix / East Valley | D7: 47.7 | E7: 31.9 | F7: 12.5 | G7: 5.8 | H7: 17.59 | I7: 170 | J7: =100-SUM(D7:G7) | K7: 5 | L7: 7 | M7: 31 | N7: 6 | O7: 49 | P7: CUSD About page lists 31 elementary schools, 5 junior highs, 2 middle schools, 5 high schools, 4 alternatives, 1 secondary, and 1 online school.
A8: Chapel Hill-Carrboro City Schools | B8: NC | C8: Research Triangle | D8: 52.52 | E8: 14.4 | F8: 15.01 | G8: 11.28 | H8: 12.69 | I8: 135 | J8: =100-SUM(D8:G8) | K8: 4 | L8: 4 | M8: 11 | N8: 1 | O8: 20
A9: Cherry Creek School District | B9: CO | C9: Denver | D9: 44.8 | E9: 24.8 | F9: 8.4 | G9: 11.4 | H9: 16.18 | I9: 210 | J9: =100-SUM(D9:G9) | K9: 8 | L9: 11 | M9: 44 | N9: 4 | O9: 67
A10: Chicago Public Schools | B10: IL | C10: Chicago | D10: 11.8 | E10: 46.4 | F10: 4.9 | G10: 34.3 | H10: 13.77 | I10: 193 | J10: =100-SUM(D10:G10) | K10: 91 | M10: 423 | O10: 514 | P10: CPS Stats & Facts lists 423 district-run elementary/K-8 schools and 91 district-run high schools. The 157 high-school grand total includes charter, contract, and SAFE schools, so the prototype now displays the district-run count because CPS salary data applies to district-run teacher placement.
A11: Cobb County School District | B11: GA | C11: Atlanta | D11: 32 | E11: 26.6 | F11: 6.2 | G11: 29.2 | H11: 14.06 | I11: 150 | J11: =100-SUM(D11:G11) | K11: 17 | L11: 26 | M11: 66 | N11: 3 | O11: 112 | P11: District page lists 66 elementary schools, 26 middle schools, 17 high schools, plus one charter school, one special education center, and one adult education center. | Q11: 2026-06-13
A12: Denver Public Schools | B12: CO | C12: Denver | D12: 25 | E12: 52 | F12: 3 | G12: 13 | H12: 15 | I12: 186.42 | J12: =100-SUM(D12:G12) | K12: 18 | L12: 12 | M12: 76 | N12: 87 | O12: 193
A13: Eanes ISD | B13: TX | C13: Austin | D13: 62 | E13: 15.4 | F13: 14.7 | G13: 0.9 | H13: 12.28 | I13: 130 | J13: =100-SUM(D13:G13) | K13: 2 | L13: 2 | M13: 5 | N13: 1 | O13: 10
A14: Flagstaff Unified School District | B14: AZ | C14: Flagstaff | D14: 39.8 | E14: 30.9 | F14: 0.8 | G14: 0.8 | H14: 15.68 | I14: 140 | J14: =100-SUM(D14:G14) | K14: 3 | L14: 2 | M14: 10 | N14: 0 | O14: 15 | P14: FUSD official about page says 15 comprehensive school sites; district school list includes 3 high schools and 2 middle schools.
A15: Glendale Union High School District | B15: AZ | C15: Phoenix Metro | D15: 23.4 | E15: 59.7 | F15: 3.2 | G15: 9.3 | H15: 22.24 | I15: 145 | J15: =100-SUM(D15:G15) | K15: 11 | L15: 0 | M15: 0 | N15: 0 | O15: 11 | P15: NCES lists 11 total schools. GUHSD is a high-school-only district; all schools counted as high schools. Substitute rate uses $145 adjusted rate of published $123-$199 daily range.
A16: Glendora Unified School District | B16: CA | C16: Southern California | D16: 28 | E16: 49 | F16: 15 | G16: 1 | H16: 24 | I16: 200 | J16: =100-SUM(D16:G16) | K16: 2 | L16: 2 | M16: 5 | N16: 1 | O16: 10
A17: Gwinnett County Public Schools | B17: GA | C17: Atlanta | D17: 14.5 | E17: 36.2 | F17: 13.1 | G17: 31.6 | H17: 14.26 | I17: 130 | J17: =100-SUM(D17:G17) | K17: 24 | L17: 29 | M17: 81 | N17: 8 | O17: 142 | P17: GCPS by the Numbers lists 81 elementary schools, 29 middle schools, 24 high schools, 7 special entities, and 1 charter school. | Q17: 2026-06-13
A18: Jordan District | B18: UT | C18: Salt Lake Valley | D18: 70 | E18: 20 | F18: 2 | G18: 1 | H18: 21 | I18: 199 | J18: =100-SUM(D18:G18) | K18: 10 | L18: 13 | M18: 42 | N18: 3 | O18: 68
A19: Katy ISD | B19: TX | C19: Houston | D19: 27 | E19: 37 | F19: 17 | G19: 15 | H19: 14 | I19: 120 | J19: =100-SUM(D19:G19) | K19: 11 | L19: 18 | M19: 48 | N19: 3 | O19: 80
A20: La Cañada Unified School District | B20: CA | C20: Southern California | D20: 42 | E20: 12 | F20: 33 | G20: 0 | H20: 23.66 | I20: 200 | J20: =100-SUM(D20:G20) | K20: 1 | L20: 1 | M20: 3 | N20: 0 | O20: 4
A21: Lake Washington School District | B21: WA | C21: Seattle Eastside | D21: 35 | E21: 15 | F21: 38 | G21: 3 | H21: 17.91 | I21: 222 | J21: =100-SUM(D21:G21) | K21: 6 | L21: 11 | M21: 33 | N21: 7 | O21: 57 | P21: https://www.lwsd.org/employment/teachers-certificated-employees/salary-schedules ; https://nces.ed.gov/ccd/districtsearch/district_detail.asp?DistrictID=5304230 ; https://www.apartments.com/rent-market-trends/redmond-wa/ ; https://www.redfin.com/city/14913/WA/Redmond/housing-market ; https://www.lwsd.org/about/enrollment-report | Q21: 2026-06-13 | R21: 9
A22: Leander ISD | B22: TX | C22: Austin | D22: 46 | E22: 26 | F22: 17 | G22: 5 | H22: 14 | I22: 130 | J22: =100-SUM(D22:G22) | K22: 6 | L22: 9 | M22: 30 | N22: 4 | O22: 49
A23: Los Angeles Unified | B23: CA | C23: Southern California | D23: 10 | E23: 73 | F23: 4 | G23: 7 | H23: 19.2 | I23: 261.49 | J23: =100-SUM(D23:G23) | O23: 784
A24: Loudoun County Public Schools | B24: VA | C24: Northern VA/DC | D24: 38 | E24: 18 | F24: 26 | G24: 7 | H24: 12.13 | I24: 135.03 | J24: =100-SUM(D24:G24) | K24: 17 | L24: 18 | M24: 62 | N24: 5 | O24: 102 | P24: LCPS operates a very large PK-12 system; NCES lists 102 total schools, and the high-school list includes 17 traditional high schools. Counts use 17 high schools, 18 middle schools, 62 elementary schools, and 5 other/specialty campuses to reconcile to 102 total schools. | Q24: 2026-06-13
A25: Madison Metropolitan School District | B25: WI | C25: Madison | D25: 39 | E25: 25 | F25: 7 | G25: 18 | H25: 11.61 | I25: 195.44 | J25: 11 | K25: 8 | L25: 12 | M25: 32 | N25: 0 | O25: 52 | P25: https://www.madison.k12.wi.us/about | Q25: 2026-06-11 | R25: 11
A26: Metro Nashville Public Schools | B26: TN | C26: Nashville | D26: 24.4 | E26: 32.2 | F26: 3.8 | G26: 39.2 | H26: 16 | I26: 145 | J26: =100-SUM(D26:G26) | K26: 21 | L26: 28 | O26: 162 | P26: MNPS official schools directory high-school filter lists 21 high schools; middle/K-8 count remains from the public school-options list.
A27: Nassau County School District | B27: FL | C27: Northeast FL | D27: 75 | E27: 11 | F27: 2 | G27: 7 | H27: 15.55 | I27: 120 | J27: =100-SUM(D27:G27) | K27: 4 | L27: 3 | M27: 9 | N27: 1 | O27: 17 | P27: https://www.nassau.k12.fl.us/page/instructional-salaries ; https://files-backend.assets.thrillshare.com/documents/asset/uploaded_file/5569/Ncsd/f73c8433-23bf-4388-aa76-259dafad90d2/24-27_NTA_Ratified_Amended_with_Signatures__25.pdf ; https://nces.ed.gov/ccd/districtsearch/district_detail.asp?ID2=1201350 ; https://www.apartments.com/rent-market-trends/yulee-fl/ ; https://www.redfin.com/zipcode/32097/housing-market | Q27: 2026-06-13 | R27: 5
A28: North Clackamas School District | B28: OR | C28: Portland | D28: 56 | E28: 20 | F28: 12 | G28: 3 | H28: 19.32 | I28: 250 | J28: =100-SUM(D28:G28) | K28: 5 | L28: 4 | M28: 18 | N28: 5 | O28: 32 | P28: District page lists 32 schools total; counts entered as 18 elementary, 4 middle, 5 high, 5 charter/CTE/specialty.
A29: Oakland Unified School District | B29: CA | C29: Bay Area | D29: 12 | E29: 47 | F29: 11 | G29: 20 | H29: 19 | I29: 337 | J29: =100-SUM(D29:G29) | O29: 80
A30: Ocean Springs School District | B30: MS | C30: Mississippi Gulf Coast | D30: 69.19 | E30: 9.02 | F30: 2.89 | G30: 12.61 | H30: 13.65 | I30: 90 | J30: =100-SUM(D30:G30) | K30: 1 | L30: 1 | M30: 4 | N30: 1 | O30: 7 | P30: NCES lists 7 schools. Counts categorize Ocean Springs High as high, Ocean Springs Middle as middle, Ocean Springs Upper Elementary plus Magnolia/Oak/Pecan Park as elementary, and Keys Vocational Center as other/specialty. Demographic percentages are summed from NCES school-level race/ethnicity counts; Other includes American Indian/Alaska Native, Native Hawaiian/Pacific Islander, and Two or More Races.
A31: Oxnard Union High School District | B31: CA | C31: Southern California | D31: 15 | E31: 80 | F31: 2 | G31: 2 | H31: 25 | I31: 185 | J31: =100-SUM(D31:G31) | K31: 12 | L31: 0 | M31: 0 | N31: 0 | O31: 12
A32: Portland Public Schools | B32: OR | C32: Portland | D32: 53.3 | E32: 18.4 | F32: 5.7 | G32: 8.3 | H32: 16.04 | I32: 275.71 | J32: =100-SUM(D32:G32) | K32: 10 | L32: 15 | M32: 45 | N32: 11 | O32: 81 | P32: PPS 2025-26 overview: 45 elementary, 10 K-8, 15 middle, 10 high, 1 K-12; total 81.
A33: Provo City School District | B33: UT | C33: Salt Lake Valley | D33: 56 | E33: 33 | F33: 2 | G33: 1 | H33: 20 | I33: 185 | J33: =100-SUM(D33:G33) | K33: 3 | L33: 2 | M33: 13 | N33: 0 | O33: 18
A34: Royal ISD | B34: TX | C34: Houston | D34: 7.9 | E34: 72.1 | F34: 1.2 | G34: 16.5 | H34: 16.81 | I34: 125 | J34: =100-SUM(D34:G34) | K34: 1 | L34: 1 | M34: 3 | N34: 1 | O34: 6 | P34: Royal ISD is a fast-growth district. Current district page lists six campuses, including Royal Prairie Elementary and Royal STEM Academy; NCES/Texas Tribune school counts lag current district listings. Substitute pay is provisional because the public 2023-2024 Substitute Pay Schedule listing did not expose the actual rate in searchable text.
A35: Saint Helena Unified School District | B35: CA | C35: Northern California | D35: 42 | E35: 53 | F35: 2 | G35: 1 | H35: 13.32 | I35: 275 | J35: =100-SUM(D35:G35) | K35: 1 | L35: 1 | M35: 2 | N35: 1 | O35: 5 | P35: District site lists St. Helena High, Robert Louis Stevenson Middle, St. Helena Elementary, St. Helena Primary, and St. Helena Opportunities Program; NCES lists 5 total schools.
A36: Salt Lake School District | B36: UT | C36: Salt Lake Valley | D36: 40 | E36: 40 | F36: 5 | G36: 5 | H36: 17 | I36: 189 | J36: =100-SUM(D36:G36) | K36: 5 | L36: 5 | M36: 21 | N36: 4 | O36: 35
A37: San Antonio ISD | B37: TX | C37: San Antonio | D37: 3 | E37: 89.6 | F37: 1.4 | G37: 6 | H37: 14.95 | I37: 140 | J37: =100-SUM(D37:G37) | K37: 14 | L37: 12 | M37: 51 | N37: 6 | O37: 83 | P37: Campus counts from Texas Tribune Schools Explorer. Demographic fields use Hispanic share from Texas Tribune, Black share from Express-News, and remaining minority/white share estimated from Public School Review summary.
A38: San Diego Unified School District | B38: CA | C38: Southern California | D38: 24 | E38: 45 | F38: 14 | G38: 7 | H38: 22 | I38: 250 | J38: =100-SUM(D38:G38) | K38: 22 | L38: 24 | M38: 117 | N38: 13 | O38: 176
A39: San Jose Unified School District | B39: CA | C39: Bay Area | D39: 21 | E39: 54 | F39: 16 | G39: 2 | H39: 21 | I39: 200 | J39: =100-SUM(D39:G39) | K39: 6 | L39: 6 | M39: 26 | N39: 3 | O39: 41
A40: Scarsdale Union Free School District | B40: NY | C40: Westchester NY | D40: 55 | E40: 9 | F40: 27 | G40: 1 | H40: 11.21 | I40: 163 | J40: 8 | K40: 1 | L40: 1 | M40: 5 | N40: 0 | O40: 7 | P40: https://www.scarsdaleschools.k12.ny.us/119192_3 ; https://go.boarddocs.com/ny/scarsdale/Board.nsf/files/D5WQJL66FCE9/%24file/MOA%20with%20Scarsdale%20Teachers%20Association%20%28STA%29.pdf ; https://www.scarsdaleschools.org/index.php?articleID=74973066&pageID=smartSiteFeed&psqFeed=true ; https://nces.ed.gov/ccd/districtsearch/district_detail.asp?ID2=3625950 ; https://www.redfin.com/city/16773/NY/Scarsdale/housing-market ; https://www.realtor.com/local/market/new-york/westchester-county/scarsdale ; https://www.indeed.com/cmp/Scarsdale-Public-Schools/salaries/Substitute-Teacher/Scarsdale-NY | Q40: 2026-06-11 | R40: 8
...

Sheet Median Home and Rent Prices
A1: District | B1: State | C1: Area | D1: Median Home Price | E1: Median Rent | F1: Median Home Price per Sq Ft | G1: PPSF Source URL
A2: Alief ISD | B2: TX | C2: Alief, TX | D2: 215000 | E2: 1350 | F2: 113
A3: Arcadia Unified School District | B3: CA | C3: Arcadia, CA | D3: 1800000 | E3: 3290 | F3: 736
A4: Austin ISD | B4: TX | C4: Austin, TX | D4: 506276 | E4: 1956 | F4: 294
A5: Barbers Hill ISD | B5: TX | C5: Mont Belvieu, TX | D5: 457726 | E5: 1496 | F5: 190 | G5: https://www.redfin.com/city/12568/TX/Mont-Belvieu/housing-market ; https://www.apartments.com/rent-market-trends/mont-belvieu-tx/
A6: Canyons School District | B6: UT | C6: Sandy / Canyons District, UT | D6: 660000 | E6: 2084 | F6: 252
A7: Chandler Unified School District | B7: AZ | C7: Chandler, AZ | D7: 520000 | E7: 2388 | F7: 286
A8: Chapel Hill-Carrboro City Schools | B8: NC | C8: Chapel Hill, NC | D8: 634403 | E8: 1850 | F8: 296
A9: Cherry Creek School District | B9: CO | C9: Aurora & Centennial, CO average | D9: 556984 | E9: 2208 | F9: 255
A10: Chicago Public Schools | B10: IL | C10: Chicago, IL | D10: 419749 | E10: 2406 | F10: 303
A11: Cobb County School District | B11: GA | C11: Marietta / Cobb County, GA | D11: 475000 | E11: 1534 | F11: 212 | G11: https://media.cobbk12.org/media/WWWCobb/medialib/teacher-salary-schedule.56404f113440.pdf ; https://www.cobbk12.org/the-district ; https://www.cobbk12.org/cobb-schools-delivers-balanced-budget-focused-on-classrooms-safety-and-long-term-stability.128573 ; https://www.cobbk12.org/substitute-teacher ; https://nces.ed.gov/ccd/districtsearch/district_detail.asp?ID2=1301290 ; https://www.apartments.com/rent-market-trends/marietta-ga/ ; https://www.redfin.com/city/12766/GA/Marietta/housing-market
A12: Denver Public Schools | B12: CO | C12: Denver, CO | D12: 542000 | E12: 2000 | F12: 367
A13: Eanes ISD | B13: TX | C13: Austin 78746 / West Lake Hills, TX | D13: 1724921 | E13: 3900 | F13: 558
A14: Flagstaff Unified School District | B14: AZ | C14: Flagstaff, AZ | D14: 710000 | E14: 2300 | F14: 368
A15: Glendale Union High School District | B15: AZ | C15: Glendale, AZ | D15: 408630 | E15: 1987 | F15: 211
A16: Glendora Unified School District | B16: CA | C16: Glendora, CA | D16: 900000 | E16: 2700 | F16: 583
A17: Gwinnett County Public Schools | B17: GA | C17: Lawrenceville / Gwinnett County, GA | D17: 365000 | E17: 1718 | F17: 165 | G17: https://resources.finalsite.net/images/v1719000691/gcpsk12org/lmrrhx4bc5hdy3ivppap/2024-2025_Teacher_Salary_Scheduleeq.pdf ; https://www.gcpsk12.org/about-us/gcps-by-the-numbers ; https://www.gcpsk12.org/about-us/careers/hr-support/substitute-management/general-information ; https://nces.ed.gov/ccd/districtsearch/district_detail.asp?ID2=1302550 ; https://www.apartments.com/rent-market-trends/lawrenceville-ga/ ; https://www.redfin.com/city/11598/GA/Lawrenceville/housing-market
A18: Jordan District | B18: UT | C18: West Jordan, UT | D18: 580000 | E18: 1689 | F18: 232
A19: Katy ISD | B19: TX | C19: Katy, TX | D19: 350000 | E19: 1650 | F19: 160
A20: La Cañada Unified School District | B20: CA | C20: La Cañada Flintridge, CA | D20: 2499891 | E20: 5900 | F20: 1030
A21: Lake Washington School District | B21: WA | C21: Redmond / Kirkland, WA | D21: 1299222 | E21: 3061 | F21: 650 | G21: https://www.lwsd.org/employment/teachers-certificated-employees/salary-schedules ; https://nces.ed.gov/ccd/districtsearch/district_detail.asp?DistrictID=5304230 ; https://www.apartments.com/rent-market-trends/redmond-wa/ ; https://www.redfin.com/city/14913/WA/Redmond/housing-market ; https://www.lwsd.org/about/enrollment-report
A22: Leander ISD | B22: TX | C22: Austin, TX | D22: 512000 | E22: 1500 | F22: 190
A23: Los Angeles Unified | B23: CA | C23: Los Angeles, CA | D23: 956465 | E23: 2650 | F23: 634
A24: Loudoun County Public Schools | B24: VA | C24: Ashburn / Loudoun County, VA | D24: 679593 | E24: 2680 | F24: 309 | G24: https://www.redfin.com/city/29015/VA/Ashburn/housing-market
A25: Madison Metropolitan School District | B25: WI | C25: Madison, WI | D25: 439737 | E25: 1655 | F25: 261
A26: Metro Nashville Public Schools | B26: TN | C26: Nashville, TN | D26: 436355 | E26: 2195 | F26: 274
A27: Nassau County School District | B27: FL | C27: Yulee / Nassau County, FL | D27: 421075 | E27: 1834 | F27: 212 | G27: https://www.nassau.k12.fl.us/page/instructional-salaries ; https://files-backend.assets.thrillshare.com/documents/asset/uploaded_file/5569/Ncsd/f73c8433-23bf-4388-aa76-259dafad90d2/24-27_NTA_Ratified_Amended_with_Signatures__25.pdf ; https://nces.ed.gov/ccd/districtsearch/district_detail.asp?ID2=1201350 ; https://www.apartments.com/rent-market-trends/yulee-fl/ ; https://www.redfin.com/zipcode/32097/housing-market
A28: North Clackamas School District | B28: OR | C28: Milwaukie / North Clackamas, OR | D28: 518000 | E28: 1699 | F28: 279
A29: Oakland Unified School District | B29: CA | C29: Oakland, CA | D29: 850000 | E29: 2700 | F29: 577
A30: Ocean Springs School District | B30: MS | C30: Ocean Springs, MS | D30: 294824 | E30: 2100 | F30: 201
A31: Oxnard Union High School District | B31: CA | C31: Oxnard, CA | D31: 767000 | E31: 2912 | F31: 514
A32: Portland Public Schools | B32: OR | C32: Portland, OR | D32: 538687 | E32: 1725 | F32: 328
A33: Provo City School District | B33: UT | C33: Provo, UT | D33: 533000 | E33: 1550 | F33: 267
A34: Royal ISD | B34: TX | C34: Brookshire/Pattison, TX | D34: 335000 | E34: 2245 | F34: 161
A35: Saint Helena Unified School District | B35: CA | C35: St. Helena, CA | D35: 2323609 | E35: 5995 | F35: 903
A36: Salt Lake School District | B36: UT | C36: Salt Lake City, UT | D36: 580000 | E36: 1600 | F36: 372
A37: San Antonio ISD | B37: TX | C37: San Antonio, TX | D37: 260000 | E37: 1372 | F37: 151
A38: San Diego Unified School District | B38: CA | C38: San Diego, CA | D38: 1000000 | E38: 3039 | F38: 687
A39: San Jose Unified School District | B39: CA | C39: San Jose, CA | D39: 1500000 | E39: 3300 | F39: 878
A40: Scarsdale Union Free School District | B40: NY | C40: Scarsdale, NY | D40: 2088750 | E40: 5500 | F40: 752 | G40: https://www.redfin.com/city/16773/NY/Scarsdale/housing-market ; https://www.realtor.com/local/market/new-york/westchester-county/scarsdale
...

Sheet District Value Scores
A1: District | B1: State | C1: Region | D1: BA Start | E1: BA 5-Year | F1: BA 10-Year | G1: MA Start | H1: MA 5-Year | I1: MA 10-Year | J1: Avg Start Salary | K1: Avg 10-Year Salary | L1: Avg Growth % | M1: Master's Premium | N1: Median Home Price | O1: Median Rent | P1: Student-Teacher Ratio | Q1: Licensed Sub Pay | R1: Salary Level Score | S1: Growth Score | T1: Master's Premium Score | U1: Salary Score | V1: Affordability Score | W1: Student-Teacher Ratio Score | X1: Sub Pay Score | Y1: Demographic Balance Score | Z1: Overall Value Score | AA1: Median Home Price per Sq Ft | AB1: Price per Sq Ft Score | AC1: Other % | AD1: Sub Pay Housing Power | AE1: Stability Score | AF1: Pre-Risk Overall | AG1: Risk Multiplier | AH1: Risk-Adjusted Note
A2: Alief ISD | B2: =IFERROR(INDEX('School District Profiles'!$B$2:$B$58,MATCH($A2,'School District Profiles'!$A$2:$A$58,0)),"") | C2: =IFERROR(INDEX('School District Profiles'!$C$2:$C$58,MATCH($A2,'School District Profiles'!$A$2:$A$58,0)),"") | D2: =SUMIFS('Teacher Salary Data'!$E$2:$E$1277,'Teacher Salary Data'!$A$2:$A$1277,$A2,'Teacher Salary Data'!$C$2:$C$1277,"Bachelor's",'Teacher Salary Data'!$D$2:$D$1277,0) | E2: =SUMIFS('Teacher Salary Data'!$E$2:$E$1277,'Teacher Salary Data'!$A$2:$A$1277,$A2,'Teacher Salary Data'!$C$2:$C$1277,"Bachelor's",'Teacher Salary Data'!$D$2:$D$1277,5) | F2: =SUMIFS('Teacher Salary Data'!$E$2:$E$1277,'Teacher Salary Data'!$A$2:$A$1277,$A2,'Teacher Salary Data'!$C$2:$C$1277,"Bachelor's",'Teacher Salary Data'!$D$2:$D$1277,10) | G2: =SUMIFS('Teacher Salary Data'!$E$2:$E$1277,'Teacher Salary Data'!$A$2:$A$1277,$A2,'Teacher Salary Data'!$C$2:$C$1277,"Master's",'Teacher Salary Data'!$D$2:$D$1277,0) | H2: =SUMIFS('Teacher Salary Data'!$E$2:$E$1277,'Teacher Salary Data'!$A$2:$A$1277,$A2,'Teacher Salary Data'!$C$2:$C$1277,"Master's",'Teacher Salary Data'!$D$2:$D$1277,5) | I2: =SUMIFS('Teacher Salary Data'!$E$2:$E$1277,'Teacher Salary Data'!$A$2:$A$1277,$A2,'Teacher Salary Data'!$C$2:$C$1277,"Master's",'Teacher Salary Data'!$D$2:$D$1277,10) | J2: =AVERAGE(D2,G2) | K2: =AVERAGE(F2,I2) | L2: =IFERROR((K2-J2)/J2,0) | M2: =G2-D2 | N2: =IFERROR(INDEX('Median Home and Rent Prices'!$D$2:$D$58,MATCH($A2,'Median Home and Rent Prices'!$A$2:$A$58,0)),0) | O2: =IFERROR(INDEX('Median Home and Rent Prices'!$E$2:$E$58,MATCH($A2,'Median Home and Rent Prices'!$A$2:$A$58,0)),0) | P2: =IFERROR(INDEX('School District Profiles'!$H$2:$H$58,MATCH($A2,'School District Profiles'!$A$2:$A$58,0)),0) | Q2: =IFERROR(INDEX('School District Profiles'!$I$2:$I$58,MATCH($A2,'School District Profiles'!$A$2:$A$58,0)),0) | R2: =IFERROR(MAX(0,MIN(100,(K2-50000)/(110000-50000)*100)),0) | S2: =IFERROR(MAX(0,MIN(100,L2/0.6*100)),0) | T2: =IFERROR(MAX(0,MIN(100,M2/15000*100)),0) | U2: =IFERROR(0.45*R2+0.4*S2+0.15*T2,0) | V2: =IFERROR(0.4*MAX(0,MIN(100,(((J2/12)/O2)-2)/(4-2)*100))+0.35*MAX(0,MIN(100,(8-(N2/K2))/(8-3)*100))+0.25*AB2,0) | W2: =IFERROR(MAX(0,MIN(100,(25-P2)/(25-12)*100)),0) | X2: =IFERROR(MAX(0,MIN(100,(AD2-1)/(3-1)*100))*IF(OR($A2="North Clackamas School District",$A2="Provo City School District"),0.6,1),0) | Y2: =IFERROR(MAX(0,MIN(100,(1-((IFERROR(INDEX('School District Profiles'!$D$2:$D$58,MATCH($A2,'School District Profiles'!$A$2:$A$58,0)),0)/100)^2+(IFERROR(INDEX('School District Profiles'!$E$2:$E$58,MATCH($A2,'School District Profiles'!$A$2:$A$58,0)),0)/100)^2+(IFERROR(INDEX('School District Profiles'!$F$2:$F$58,MATCH($A2,'School District Profiles'!$A$2:$A$58,0)),0)/100)^2+(IFERROR(INDEX('School District Profiles'!$G$2:$G$58,MATCH($A2,'School District Profiles'!$A$2:$A$58,0)),0)/100)^2+(AC2/100)^2))/0.8*100)),0) | Z2: =IFERROR(AF2*AG2,0) | AA2: =IFERROR(INDEX('Median Home and Rent Prices'!$F$2:$F$58,MATCH($A2,'Median Home and Rent Prices'!$A$2:$A$58,0)),0) | AB2: =IFERROR(MAX(0,MIN(100,(800-AA2)/(800-150)*100)),0) | AC2: =IFERROR(INDEX('School District Profiles'!$J$2:$J$58,MATCH($A2,'School District Profiles'!$A$2:$A$58,0)),0) | AD2: =IFERROR(Q2*20/O2,0) | AE2: =IFERROR(IF(AG2>=1,100,IF(AG2>=0.95,75,IF(AG2>=0.9,60,IF(AG2>=0.85,40,IF(AG2>=0.8,25,0))))),0) | AF2: =IFERROR(0.4*U2+0.3*V2+0.1*W2+0.1*X2+0.1*Y2,0) | AG2: 0.9 | AH2: 10% employment-stability penalty due to enrollment-loss pressure, charter competition, and budget-cut concerns.
A3: Arcadia Unified School District | B3: =IFERROR(INDEX('School District Profiles'!$B$2:$B$58,MATCH($A3,'School District Profiles'!$A$2:$A$58,0)),"") | C3: =IFERROR(INDEX('School District Profiles'!$C$2:$C$58,MATCH($A3,'School District Profiles'!$A$2:$A$58,0)),"") | D3: =SUMIFS('Teacher Salary Data'!$E$2:$E$1277,'Teacher Salary Data'!$A$2:$A$1277,$A3,'Teacher Salary Data'!$C$2:$C$1277,"Bachelor's",'Teacher Salary Data'!$D$2:$D$1277,0) | E3: =SUMIFS('Teacher Salary Data'!$E$2:$E$1277,'Teacher Salary Data'!$A$2:$A$1277,$A3,'Teacher Salary Data'!$C$2:$C$1277,"Bachelor's",'Teacher Salary Data'!$D$2:$D$1277,5) | F3: =SUMIFS('Teacher Salary Data'!$E$2:$E$1277,'Teacher Salary Data'!$A$2:$A$1277,$A3,'Teacher Salary Data'!$C$2:$C$1277,"Bachelor's",'Teacher Salary Data'!$D$2:$D$1277,10) | G3: =SUMIFS('Teacher Salary Data'!$E$2:$E$1277,'Teacher Salary Data'!$A$2:$A$1277,$A3,'Teacher Salary Data'!$C$2:$C$1277,"Master's",'Teacher Salary Data'!$D$2:$D$1277,0) | H3: =SUMIFS('Teacher Salary Data'!$E$2:$E$1277,'Teacher Salary Data'!$A$2:$A$1277,$A3,'Teacher Salary Data'!$C$2:$C$1277,"Master's",'Teacher Salary Data'!$D$2:$D$1277,5) | I3: =SUMIFS('Teacher Salary Data'!$E$2:$E$1277,'Teacher Salary Data'!$A$2:$A$1277,$A3,'Teacher Salary Data'!$C$2:$C$1277,"Master's",'Teacher Salary Data'!$D$2:$D$1277,10) | J3: =AVERAGE(D3,G3) | K3: =AVERAGE(F3,I3) | L3: =IFERROR((K3-J3)/J3,0) | M3: =G3-D3 | N3: =IFERROR(INDEX('Median Home and Rent Prices'!$D$2:$D$58,MATCH($A3,'Median Home and Rent Prices'!$A$2:$A$58,0)),0) | O3: =IFERROR(INDEX('Median Home and Rent Prices'!$E$2:$E$58,MATCH($A3,'Median Home and Rent Prices'!$A$2:$A$58,0)),0) | P3: =IFERROR(INDEX('School District Profiles'!$H$2:$H$58,MATCH($A3,'School District Profiles'!$A$2:$A$58,0)),0) | Q3: =IFERROR(INDEX('School District Profiles'!$I$2:$I$58,MATCH($A3,'School District Profiles'!$A$2:$A$58,0)),0) | R3: =IFERROR(MAX(0,MIN(100,(K3-50000)/(110000-50000)*100)),0) | S3: =IFERROR(MAX(0,MIN(100,L3/0.6*100)),0) | T3: =IFERROR(MAX(0,MIN(100,M3/15000*100)),0) | U3: =IFERROR(0.45*R3+0.4*S3+0.15*T3,0) | V3: =IFERROR(0.4*MAX(0,MIN(100,(((J3/12)/O3)-2)/(4-2)*100))+0.35*MAX(0,MIN(100,(8-(N3/K3))/(8-3)*100))+0.25*AB3,0) | W3: =IFERROR(MAX(0,MIN(100,(25-P3)/(25-12)*100)),0) | X3: =IFERROR(MAX(0,MIN(100,(AD3-1)/(3-1)*100))*IF(OR($A3="North Clackamas School District",$A3="Provo City School District"),0.6,1),0) | Y3: =IFERROR(MAX(0,MIN(100,(1-((IFERROR(INDEX('School District Profiles'!$D$2:$D$58,MATCH($A3,'School District Profiles'!$A$2:$A$58,0)),0)/100)^2+(IFERROR(INDEX('School District Profiles'!$E$2:$E$58,MATCH($A3,'School District Profiles'!$A$2:$A$58,0)),0)/100)^2+(IFERROR(INDEX('School District Profiles'!$F$2:$F$58,MATCH($A3,'School District Profiles'!$A$2:$A$58,0)),0)/100)^2+(IFERROR(INDEX('School District Profiles'!$G$2:$G$58,MATCH($A3,'School District Profiles'!$A$2:$A$58,0)),0)/100)^2+(AC3/100)^2))/0.8*100)),0) | Z3: =IFERROR(AF3*AG3,0) | AA3: =IFERROR(INDEX('Median Home and Rent Prices'!$F$2:$F$58,MATCH($A3,'Median Home and Rent Prices'!$A$2:$A$58,0)),0) | AB3: =IFERROR(MAX(0,MIN(100,(800-AA3)/(800-150)*100)),0) | AC3: =IFERROR(INDEX('School District Profiles'!$J$2:$J$58,MATCH($A3,'School District Profiles'!$A$2:$A$58,0)),0) | AD3: =IFERROR(Q3*20/O3,0) | AE3: =IFERROR(IF(AG3>=1,100,IF(AG3>=0.95,75,IF(AG3>=0.9,60,IF(AG3>=0.85,40,IF(AG3>=0.8,25,0))))),0) | AF3: =IFERROR(0.4*U3+0.3*V3+0.1*W3+0.1*X3+0.1*Y3,0) | AG3: 0.85 | AH3: 15% employment-stability penalty because district budget updates indicated teacher-layoff risk unless local funding support fills the gap.
A4: Austin ISD | B4: =IFERROR(INDEX('School District Profiles'!$B$2:$B$58,MATCH($A4,'School District Profiles'!$A$2:$A$58,0)),"") | C4: =IFERROR(INDEX('School District Profiles'!$C$2:$C$58,MATCH($A4,'School District Profiles'!$A$2:$A$58,0)),"") | D4: =SUMIFS('Teacher Salary Data'!$E$2:$E$1277,'Teacher Salary Data'!$A$2:$A$1277,$A4,'Teacher Salary Data'!$C$2:$C$1277,"Bachelor's",'Teacher Salary Data'!$D$2:$D$1277,0) | E4: =SUMIFS('Teacher Salary Data'!$E$2:$E$1277,'Teacher Salary Data'!$A$2:$A$1277,$A4,'Teacher Salary Data'!$C$2:$C$1277,"Bachelor's",'Teacher Salary Data'!$D$2:$D$1277,5) | F4: =SUMIFS('Teacher Salary Data'!$E$2:$E$1277,'Teacher Salary Data'!$A$2:$A$1277,$A4,'Teacher Salary Data'!$C$2:$C$1277,"Bachelor's",'Teacher Salary Data'!$D$2:$D$1277,10) | G4: =SUMIFS('Teacher Salary Data'!$E$2:$E$1277,'Teacher Salary Data'!$A$2:$A$1277,$A4,'Teacher Salary Data'!$C$2:$C$1277,"Master's",'Teacher Salary Data'!$D$2:$D$1277,0) | H4: =SUMIFS('Teacher Salary Data'!$E$2:$E$1277,'Teacher Salary Data'!$A$2:$A$1277,$A4,'Teacher Salary Data'!$C$2:$C$1277,"Master's",'Teacher Salary Data'!$D$2:$D$1277,5) | I4: =SUMIFS('Teacher Salary Data'!$E$2:$E$1277,'Teacher Salary Data'!$A$2:$A$1277,$A4,'Teacher Salary Data'!$C$2:$C$1277,"Master's",'Teacher Salary Data'!$D$2:$D$1277,10) | J4: =AVERAGE(D4,G4) | K4: =AVERAGE(F4,I4) | L4: =IFERROR((K4-J4)/J4,0) | M4: =G4-D4 | N4: =IFERROR(INDEX('Median Home and Rent Prices'!$D$2:$D$58,MATCH($A4,'Median Home and Rent Prices'!$A$2:$A$58,0)),0) | O4: =IFERROR(INDEX('Median Home and Rent Prices'!$E$2:$E$58,MATCH($A4,'Median Home and Rent Prices'!$A$2:$A$58,0)),0) | P4: =IFERROR(INDEX('School District Profiles'!$H$2:$H$58,MATCH($A4,'School District Profiles'!$A$2:$A$58,0)),0) | Q4: =IFERROR(INDEX('School District Profiles'!$I$2:$I$58,MATCH($A4,'School District Profiles'!$A$2:$A$58,0)),0) | R4: =IFERROR(MAX(0,MIN(100,(K4-50000)/(110000-50000)*100)),0) | S4: =IFERROR(MAX(0,MIN(100,L4/0.6*100)),0) | T4: =IFERROR(MAX(0,MIN(100,M4/15000*100)),0) | U4: =IFERROR(0.45*R4+0.4*S4+0.15*T4,0) | V4: =IFERROR(0.4*MAX(0,MIN(100,(((J4/12)/O4)-2)/(4-2)*100))+0.35*MAX(0,MIN(100,(8-(N4/K4))/(8-3)*100))+0.25*AB4,0) | W4: =IFERROR(MAX(0,MIN(100,(25-P4)/(25-12)*100)),0) | X4: =IFERROR(MAX(0,MIN(100,(AD4-1)/(3-1)*100))*IF(OR($A4="North Clackamas School District",$A4="Provo City School District"),0.6,1),0) | Y4: =IFERROR(MAX(0,MIN(100,(1-((IFERROR(INDEX('School District Profiles'!$D$2:$D$58,MATCH($A4,'School District Profiles'!$A$2:$A$58,0)),0)/100)^2+(IFERROR(INDEX('School District Profiles'!$E$2:$E$58,MATCH($A4,'School District Profiles'!$A$2:$A$58,0)),0)/100)^2+(IFERROR(INDEX('School District Profiles'!$F$2:$F$58,MATCH($A4,'School District Profiles'!$A$2:$A$58,0)),0)/100)^2+(IFERROR(INDEX('School District Profiles'!$G$2:$G$58,MATCH($A4,'School District Profiles'!$A$2:$A$58,0)),0)/100)^2+(AC4/100)^2))/0.8*100)),0) | Z4: =IFERROR(AF4*AG4,0) | AA4: =IFERROR(INDEX('Median Home and Rent Prices'!$F$2:$F$58,MATCH($A4,'Median Home and Rent Prices'!$A$2:$A$58,0)),0) | AB4: =IFERROR(MAX(0,MIN(100,(800-AA4)/(800-150)*100)),0) | AC4: =IFERROR(INDEX('School District Profiles'!$J$2:$J$58,MATCH($A4,'School District Profiles'!$A$2:$A$58,0)),0) | AD4: =IFERROR(Q4*20/O4,0) | AE4: =IFERROR(IF(AG4>=1,100,IF(AG4>=0.95,75,IF(AG4>=0.9,60,IF(AG4>=0.85,40,IF(AG4>=0.8,25,0))))),0) | AF4: =IFERROR(0.4*U4+0.3*V4+0.1*W4+0.1*X4+0.1*Y4,0) | AG4: 0.8 | AH4: 20% employment-stability penalty due to very large projected budget gap, planned job cuts, school-closure discussions, and possible governance/fiscal instability.
A5: Barbers Hill ISD | B5: =IFERROR(INDEX('School District Profiles'!$B$2:$B$58,MATCH($A5,'School District Profiles'!$A$2:$A$58,0)),"") | C5: =IFERROR(INDEX('School District Profiles'!$C$2:$C$58,MATCH($A5,'School District Profiles'!$A$2:$A$58,0)),"") | D5: =SUMIFS('Teacher Salary Data'!$E$2:$E$1277,'Teacher Salary Data'!$A$2:$A$1277,$A5,'Teacher Salary Data'!$C$2:$C$1277,"Bachelor's",'Teacher Salary Data'!$D$2:$D$1277,0) | E5: =SUMIFS('Teacher Salary Data'!$E$2:$E$1277,'Teacher Salary Data'!$A$2:$A$1277,$A5,'Teacher Salary Data'!$C$2:$C$1277,"Bachelor's",'Teacher Salary Data'!$D$2:$D$1277,5) | F5: =SUMIFS('Teacher Salary Data'!$E$2:$E$1277,'Teacher Salary Data'!$A$2:$A$1277,$A5,'Teacher Salary Data'!$C$2:$C$1277,"Bachelor's",'Teacher Salary Data'!$D$2:$D$1277,10) | G5: =SUMIFS('Teacher Salary Data'!$E$2:$E$1277,'Teacher Salary Data'!$A$2:$A$1277,$A5,'Teacher Salary Data'!$C$2:$C$1277,"Master's",'Teacher Salary Data'!$D$2:$D$1277,0) | H5: =SUMIFS('Teacher Salary Data'!$E$2:$E$1277,'Teacher Salary Data'!$A$2:$A$1277,$A5,'Teacher Salary Data'!$C$2:$C$1277,"Master's",'Teacher Salary Data'!$D$2:$D$1277,5) | I5: =SUMIFS('Teacher Salary Data'!$E$2:$E$1277,'Teacher Salary Data'!$A$2:$A$1277,$A5,'Teacher Salary Data'!$C$2:$C$1277,"Master's",'Teacher Salary Data'!$D$2:$D$1277,10) | J5: =AVERAGE(D5,G5) | K5: =AVERAGE(F5,I5) | L5: =IFERROR((K5-J5)/J5,0) | M5: =G5-D5 | N5: =IFERROR(INDEX('Median Home and Rent Prices'!$D$2:$D$58,MATCH($A5,'Median Home and Rent Prices'!$A$2:$A$58,0)),0) | O5: =IFERROR(INDEX('Median Home and Rent Prices'!$E$2:$E$58,MATCH($A5,'Median Home and Rent Prices'!$A$2:$A$58,0)),0) | P5: =IFERROR(INDEX('School District Profiles'!$H$2:$H$58,MATCH($A5,'School District Profiles'!$A$2:$A$58,0)),0) | Q5: =IFERROR(INDEX('School District Profiles'!$I$2:$I$58,MATCH($A5,'School District Profiles'!$A$2:$A$58,0)),0) | R5: =IFERROR(MAX(0,MIN(100,(K5-50000)/(110000-50000)*100)),0) | S5: =IFERROR(MAX(0,MIN(100,L5/0.6*100)),0) | T5: =IFERROR(MAX(0,MIN(100,M5/15000*100)),0) | U5: =IFERROR(0.45*R5+0.4*S5+0.15*T5,0) | V5: =IFERROR(0.4*MAX(0,MIN(100,(((J5/12)/O5)-2)/(4-2)*100))+0.35*MAX(0,MIN(100,(8-(N5/K5))/(8-3)*100))+0.25*AB5,0) | W5: =IFERROR(MAX(0,MIN(100,(25-P5)/(25-12)*100)),0) | X5: =IFERROR(MAX(0,MIN(100,(AD5-1)/(3-1)*100))*IF(OR($A5="North Clackamas School District",$A5="Provo City School District"),0.6,1),0) | Y5: =IFERROR(MAX(0,MIN(100,(1-((IFERROR(INDEX('School District Profiles'!$D$2:$D$58,MATCH($A5,'School District Profiles'!$A$2:$A$58,0)),0)/100)^2+(IFERROR(INDEX('School District Profiles'!$E$2:$E$58,MATCH($A5,'School District Profiles'!$A$2:$A$58,0)),0)/100)^2+(IFERROR(INDEX('School District Profiles'!$F$2:$F$58,MATCH($A5,'School District Profiles'!$A$2:$A$58,0)),0)/100)^2+(IFERROR(INDEX('School District Profiles'!$G$2:$G$58,MATCH($A5,'School District Profiles'!$A$2:$A$58,0)),0)/100)^2+(AC5/100)^2))/0.8*100)),0) | Z5: =IFERROR(AF5*AG5,0) | AA5: =IFERROR(INDEX('Median Home and Rent Prices'!$F$2:$F$58,MATCH($A5,'Median Home and Rent Prices'!$A$2:$A$58,0)),0) | AB5: =IFERROR(MAX(0,MIN(100,(800-AA5)/(800-150)*100)),0) | AC5: =IFERROR(INDEX('School District Profiles'!$J$2:$J$58,MATCH($A5,'School District Profiles'!$A$2:$A$58,0)),0) | AD5: =IFERROR(Q5*20/O5,0) | AE5: =IFERROR(IF(AG5>=1,100,IF(AG5>=0.95,75,IF(AG5>=0.9,60,IF(AG5>=0.85,40,IF(AG5>=0.8,25,0))))),0) | AF5: =IFERROR(0.4*U5+0.3*V5+0.1*W5+0.1*X5+0.1*Y5,0) | AG5: 1 | AH5: No penalty applied. Low current layoff risk: Barbers Hill shows strong enrollment growth and public-facing hiring/retention language; no current public evidence found of broad layoffs, closures, or fiscal-crisis cuts in this pass.
A6: Canyons School District | B6: =IFERROR(INDEX('School District Profiles'!$B$2:$B$58,MATCH($A6,'School District Profiles'!$A$2:$A$58,0)),"") | C6: =IFERROR(INDEX('School District Profiles'!$C$2:$C$58,MATCH($A6,'School District Profiles'!$A$2:$A$58,0)),"") | D6: =SUMIFS('Teacher Salary Data'!$E$2:$E$1277,'Teacher Salary Data'!$A$2:$A$1277,$A6,'Teacher Salary Data'!$C$2:$C$1277,"Bachelor's",'Teacher Salary Data'!$D$2:$D$1277,0) | E6: =SUMIFS('Teacher Salary Data'!$E$2:$E$1277,'Teacher Salary Data'!$A$2:$A$1277,$A6,'Teacher Salary Data'!$C$2:$C$1277,"Bachelor's",'Teacher Salary Data'!$D$2:$D$1277,5) | F6: =SUMIFS('Teacher Salary Data'!$E$2:$E$1277,'Teacher Salary Data'!$A$2:$A$1277,$A6,'Teacher Salary Data'!$C$2:$C$1277,"Bachelor's",'Teacher Salary Data'!$D$2:$D$1277,10) | G6: =SUMIFS('Teacher Salary Data'!$E$2:$E$1277,'Teacher Salary Data'!$A$2:$A$1277,$A6,'Teacher Salary Data'!$C$2:$C$1277,"Master's",'Teacher Salary Data'!$D$2:$D$1277,0) | H6: =SUMIFS('Teacher Salary Data'!$E$2:$E$1277,'Teacher Salary Data'!$A$2:$A$1277,$A6,'Teacher Salary Data'!$C$2:$C$1277,"Master's",'Teacher Salary Data'!$D$2:$D$1277,5) | I6: =SUMIFS('Teacher Salary Data'!$E$2:$E$1277,'Teacher Salary Data'!$A$2:$A$1277,$A6,'Teacher Salary Data'!$C$2:$C$1277,"Master's",'Teacher Salary Data'!$D$2:$D$1277,10) | J6: =AVERAGE(D6,G6) | K6: =AVERAGE(F6,I6) | L6: =IFERROR((K6-J6)/J6,0) | M6: =G6-D6 | N6: =IFERROR(INDEX('Median Home and Rent Prices'!$D$2:$D$58,MATCH($A6,'Median Home and Rent Prices'!$A$2:$A$58,0)),0) | O6: =IFERROR(INDEX('Median Home and Rent Prices'!$E$2:$E$58,MATCH($A6,'Median Home and Rent Prices'!$A$2:$A$58,0)),0) | P6: =IFERROR(INDEX('School District Profiles'!$H$2:$H$58,MATCH($A6,'School District Profiles'!$A$2:$A$58,0)),0) | Q6: =IFERROR(INDEX('School District Profiles'!$I$2:$I$58,MATCH($A6,'School District Profiles'!$A$2:$A$58,0)),0) | R6: =IFERROR(MAX(0,MIN(100,(K6-50000)/(110000-50000)*100)),0) | S6: =IFERROR(MAX(0,MIN(100,L6/0.6*100)),0) | T6: =IFERROR(MAX(0,MIN(100,M6/15000*100)),0) | U6: =IFERROR(0.45*R6+0.4*S6+0.15*T6,0) | V6: =IFERROR(0.4*MAX(0,MIN(100,(((J6/12)/O6)-2)/(4-2)*100))+0.35*MAX(0,MIN(100,(8-(N6/K6))/(8-3)*100))+0.25*AB6,0) | W6: =IFERROR(MAX(0,MIN(100,(25-P6)/(25-12)*100)),0) | X6: =IFERROR(MAX(0,MIN(100,(AD6-1)/(3-1)*100))*IF(OR($A6="North Clackamas School District",$A6="Provo City School District"),0.6,1),0) | Y6: =IFERROR(MAX(0,MIN(100,(1-((IFERROR(INDEX('School District Profiles'!$D$2:$D$58,MATCH($A6,'School District Profiles'!$A$2:$A$58,0)),0)/100)^2+(IFERROR(INDEX('School District Profiles'!$E$2:$E$58,MATCH($A6,'School District Profiles'!$A$2:$A$58,0)),0)/100)^2+(IFERROR(INDEX('School District Profiles'!$F$2:$F$58,MATCH($A6,'School District Profiles'!$A$2:$A$58,0)),0)/100)^2+(IFERROR(INDEX('School District Profiles'!$G$2:$G$58,MATCH($A6,'School District Profiles'!$A$2:$A$58,0)),0)/100)^2+(AC6/100)^2))/0.8*100)),0) | Z6: =IFERROR(AF6*AG6,0) | AA6: =IFERROR(INDEX('Median Home and Rent Prices'!$F$2:$F$58,MATCH($A6,'Median Home and Rent Prices'!$A$2:$A$58,0)),0) | AB6: =IFERROR(MAX(0,MIN(100,(800-AA6)/(800-150)*100)),0) | AC6: =IFERROR(INDEX('School District Profiles'!$J$2:$J$58,MATCH($A6,'School District Profiles'!$A$2:$A$58,0)),0) | AD6: =IFERROR(Q6*20/O6,0) | AE6: =IFERROR(IF(AG6>=1,100,IF(AG6>=0.95,75,IF(AG6>=0.9,60,IF(AG6>=0.85,40,IF(AG6>=0.8,25,0))))),0) | AF6: =IFERROR(0.4*U6+0.3*V6+0.1*W6+0.1*X6+0.1*Y6,0) | AG6: 0.9 | AH6: 10% employment-stability penalty due to declining enrollment and possible elementary-school changes/closures; no broad layoff evidence found in first pass.
A7: Chandler Unified School District | B7: =IFERROR(INDEX('School District Profiles'!$B$2:$B$58,MATCH($A7,'School District Profiles'!$A$2:$A$58,0)),"") | C7: =IFERROR(INDEX('School District Profiles'!$C$2:$C$58,MATCH($A7,'School District Profiles'!$A$2:$A$58,0)),"") | D7: =SUMIFS('Teacher Salary Data'!$E$2:$E$1277,'Teacher Salary Data'!$A$2:$A$1277,$A7,'Teacher Salary Data'!$C$2:$C$1277,"Bachelor's",'Teacher Salary Data'!$D$2:$D$1277,0) | E7: =SUMIFS('Teacher Salary Data'!$E$2:$E$1277,'Teacher Salary Data'!$A$2:$A$1277,$A7,'Teacher Salary Data'!$C$2:$C$1277,"Bachelor's",'Teacher Salary Data'!$D$2:$D$1277,5) | F7: =SUMIFS('Teacher Salary Data'!$E$2:$E$1277,'Teacher Salary Data'!$A$2:$A$1277,$A7,'Teacher Salary Data'!$C$2:$C$1277,"Bachelor's",'Teacher Salary Data'!$D$2:$D$1277,10) | G7: =SUMIFS('Teacher Salary Data'!$E$2:$E$1277,'Teacher Salary Data'!$A$2:$A$1277,$A7,'Teacher Salary Data'!$C$2:$C$1277,"Master's",'Teacher Salary Data'!$D$2:$D$1277,0) | H7: =SUMIFS('Teacher Salary Data'!$E$2:$E$1277,'Teacher Salary Data'!$A$2:$A$1277,$A7,'Teacher Salary Data'!$C$2:$C$1277,"Master's",'Teacher Salary Data'!$D$2:$D$1277,5) | I7: =SUMIFS('Teacher Salary Data'!$E$2:$E$1277,'Teacher Salary Data'!$A$2:$A$1277,$A7,'Teacher Salary Data'!$C$2:$C$1277,"Master's",'Teacher Salary Data'!$D$2:$D$1277,10) | J7: =AVERAGE(D7,G7) | K7: =AVERAGE(F7,I7) | L7: =IFERROR((K7-J7)/J7,0) | M7: =G7-D7 | N7: =IFERROR(INDEX('Median Home and Rent Prices'!$D$2:$D$58,MATCH($A7,'Median Home and Rent Prices'!$A$2:$A$58,0)),0) | O7: =IFERROR(INDEX('Median Home and Rent Prices'!$E$2:$E$58,MATCH($A7,'Median Home and Rent Prices'!$A$2:$A$58,0)),0) | P7: =IFERROR(INDEX('School District Profiles'!$H$2:$H$58,MATCH($A7,'School District Profiles'!$A$2:$A$58,0)),0) | Q7: =IFERROR(INDEX('School District Profiles'!$I$2:$I$58,MATCH($A7,'School District Profiles'!$A$2:$A$58,0)),0) | R7: =IFERROR(MAX(0,MIN(100,(K7-50000)/(110000-50000)*100)),0) | S7: =IFERROR(MAX(0,MIN(100,L7/0.6*100)),0) | T7: =IFERROR(MAX(0,MIN(100,M7/15000*100)),0) | U7: =IFERROR(0.45*R7+0.4*S7+0.15*T7,0) | V7: =IFERROR(0.4*MAX(0,MIN(100,(((J7/12)/O7)-2)/(4-2)*100))+0.35*MAX(0,MIN(100,(8-(N7/K7))/(8-3)*100))+0.25*AB7,0) | W7: =IFERROR(MAX(0,MIN(100,(25-P7)/(25-12)*100)),0) | X7: =IFERROR(MAX(0,MIN(100,(AD7-1)/(3-1)*100))*IF(OR($A7="North Clackamas School District",$A7="Provo City School District"),0.6,1),0) | Y7: =IFERROR(MAX(0,MIN(100,(1-((IFERROR(INDEX('School District Profiles'!$D$2:$D$58,MATCH($A7,'School District Profiles'!$A$2:$A$58,0)),0)/100)^2+(IFERROR(INDEX('School District Profiles'!$E$2:$E$58,MATCH($A7,'School District Profiles'!$A$2:$A$58,0)),0)/100)^2+(IFERROR(INDEX('School District Profiles'!$F$2:$F$58,MATCH($A7,'School District Profiles'!$A$2:$A$58,0)),0)/100)^2+(IFERROR(INDEX('School District Profiles'!$G$2:$G$58,MATCH($A7,'School District Profiles'!$A$2:$A$58,0)),0)/100)^2+(AC7/100)^2))/0.8*100)),0) | Z7: =IFERROR(AF7*AG7,0) | AA7: =IFERROR(INDEX('Median Home and Rent Prices'!$F$2:$F$58,MATCH($A7,'Median Home and Rent Prices'!$A$2:$A$58,0)),0) | AB7: =IFERROR(MAX(0,MIN(100,(800-AA7)/(800-150)*100)),0) | AC7: =IFERROR(INDEX('School District Profiles'!$J$2:$J$58,MATCH($A7,'School District Profiles'!$A$2:$A$58,0)),0) | AD7: =IFERROR(Q7*20/O7,0) | AE7: =IFERROR(IF(AG7>=1,100,IF(AG7>=0.95,75,IF(AG7>=0.9,60,IF(AG7>=0.85,40,IF(AG7>=0.8,25,0))))),0) | AF7: =IFERROR(0.4*U7+0.3*V7+0.1*W7+0.1*X7+0.1*Y7,0) | AG7: 0.85 | AH7: 15% employment-stability penalty due to declining enrollment, budget shortfall, and staffing-reduction/job-cut plan.
A8: Chapel Hill-Carrboro City Schools | B8: =IFERROR(INDEX('School District Profiles'!$B$2:$B$58,MATCH($A8,'School District Profiles'!$A$2:$A$58,0)),"") | C8: =IFERROR(INDEX('School District Profiles'!$C$2:$C$58,MATCH($A8,'School District Profiles'!$A$2:$A$58,0)),"") | D8: =SUMIFS('Teacher Salary Data'!$E$2:$E$1277,'Teacher Salary Data'!$A$2:$A$1277,$A8,'Teacher Salary Data'!$C$2:$C$1277,"Bachelor's",'Teacher Salary Data'!$D$2:$D$1277,0) | E8: =SUMIFS('Teacher Salary Data'!$E$2:$E$1277,'Teacher Salary Data'!$A$2:$A$1277,$A8,'Teacher Salary Data'!$C$2:$C$1277,"Bachelor's",'Teacher Salary Data'!$D$2:$D$1277,5) | F8: =SUMIFS('Teacher Salary Data'!$E$2:$E$1277,'Teacher Salary Data'!$A$2:$A$1277,$A8,'Teacher Salary Data'!$C$2:$C$1277,"Bachelor's",'Teacher Salary Data'!$D$2:$D$1277,10) | G8: =SUMIFS('Teacher Salary Data'!$E$2:$E$1277,'Teacher Salary Data'!$A$2:$A$1277,$A8,'Teacher Salary Data'!$C$2:$C$1277,"Master's",'Teacher Salary Data'!$D$2:$D$1277,0) | H8: =SUMIFS('Teacher Salary Data'!$E$2:$E$1277,'Teacher Salary Data'!$A$2:$A$1277,$A8,'Teacher Salary Data'!$C$2:$C$1277,"Master's",'Teacher Salary Data'!$D$2:$D$1277,5) | I8: =SUMIFS('Teacher Salary Data'!$E$2:$E$1277,'Teacher Salary Data'!$A$2:$A$1277,$A8,'Teacher Salary Data'!$C$2:$C$1277,"Master's",'Teacher Salary Data'!$D$2:$D$1277,10) | J8: =AVERAGE(D8,G8) | K8: =AVERAGE(F8,I8) | L8: =IFERROR((K8-J8)/J8,0) | M8: =G8-D8 | N8: =IFERROR(INDEX('Median Home and Rent Prices'!$D$2:$D$58,MATCH($A8,'Median Home and Rent Prices'!$A$2:$A$58,0)),0) | O8: =IFERROR(INDEX('Median Home and Rent Prices'!$E$2:$E$58,MATCH($A8,'Median Home and Rent Prices'!$A$2:$A$58,0)),0) | P8: =IFERROR(INDEX('School District Profiles'!$H$2:$H$58,MATCH($A8,'School District Profiles'!$A$2:$A$58,0)),0) | Q8: =IFERROR(INDEX('School District Profiles'!$I$2:$I$58,MATCH($A8,'School District Profiles'!$A$2:$A$58,0)),0) | R8: =IFERROR(MAX(0,MIN(100,(K8-50000)/(110000-50000)*100)),0) | S8: =IFERROR(MAX(0,MIN(100,L8/0.6*100)),0) | T8: =IFERROR(MAX(0,MIN(100,M8/15000*100)),0) | U8: =IFERROR(0.45*R8+0.4*S8+0.15*T8,0) | V8: =IFERROR(0.4*MAX(0,MIN(100,(((J8/12)/O8)-2)/(4-2)*100))+0.35*MAX(0,MIN(100,(8-(N8/K8))/(8-3)*100))+0.25*AB8,0) | W8: =IFERROR(MAX(0,MIN(100,(25-P8)/(25-12)*100)),0) | X8: =IFERROR(MAX(0,MIN(100,(AD8-1)/(3-1)*100))*IF(OR($A8="North Clackamas School District",$A8="Provo City School District"),0.6,1),0) | Y8: =IFERROR(MAX(0,MIN(100,(1-((IFERROR(INDEX('School District Profiles'!$D$2:$D$58,MATCH($A8,'School District Profiles'!$A$2:$A$58,0)),0)/100)^2+(IFERROR(INDEX('School District Profiles'!$E$2:$E$58,MATCH($A8,'School District Profiles'!$A$2:$A$58,0)),0)/100)^2+(IFERROR(INDEX('School District Profiles'!$F$2:$F$58,MATCH($A8,'School District Profiles'!$A$2:$A$58,0)),0)/100)^2+(IFERROR(INDEX('School District Profiles'!$G$2:$G$58,MATCH($A8,'School District Profiles'!$A$2:$A$58,0)),0)/100)^2+(AC8/100)^2))/0.8*100)),0) | Z8: =IFERROR(AF8*AG8,0) | AA8: =IFERROR(INDEX('Median Home and Rent Prices'!$F$2:$F$58,MATCH($A8,'Median Home and Rent Prices'!$A$2:$A$58,0)),0) | AB8: =IFERROR(MAX(0,MIN(100,(800-AA8)/(800-150)*100)),0) | AC8: =IFERROR(INDEX('School District Profiles'!$J$2:$J$58,MATCH($A8,'School District Profiles'!$A$2:$A$58,0)),0) | AD8: =IFERROR(Q8*20/O8,0) | AE8: =IFERROR(IF(AG8>=1,100,IF(AG8>=0.95,75,IF(AG8>=0.9,60,IF(AG8>=0.85,40,IF(AG8>=0.8,25,0))))),0) | AF8: =IFERROR(0.4*U8+0.3*V8+0.1*W8+0.1*X8+0.1*Y8,0) | AG8: 0.85 | AH8: 15% employment-stability penalty due to staff cuts, school-closure discussions, declining enrollment, and budget shortfall concerns.
A9: Cherry Creek School District | B9: =IFERROR(INDEX('School District Profiles'!$B$2:$B$58,MATCH($A9,'School District Profiles'!$A$2:$A$58,0)),"") | C9: =IFERROR(INDEX('School District Profiles'!$C$2:$C$58,MATCH($A9,'School District Profiles'!$A$2:$A$58,0)),"") | D9: =SUMIFS('Teacher Salary Data'!$E$2:$E$1277,'Teacher Salary Data'!$A$2:$A$1277,$A9,'Teacher Salary Data'!$C$2:$C$1277,"Bachelor's",'Teacher Salary Data'!$D$2:$D$1277,0) | E9: =SUMIFS('Teacher Salary Data'!$E$2:$E$1277,'Teacher Salary Data'!$A$2:$A$1277,$A9,'Teacher Salary Data'!$C$2:$C$1277,"Bachelor's",'Teacher Salary Data'!$D$2:$D$1277,5) | F9: =SUMIFS('Teacher Salary Data'!$E$2:$E$1277,'Teacher Salary Data'!$A$2:$A$1277,$A9,'Teacher Salary Data'!$C$2:$C$1277,"Bachelor's",'Teacher Salary Data'!$D$2:$D$1277,10) | G9: =SUMIFS('Teacher Salary Data'!$E$2:$E$1277,'Teacher Salary Data'!$A$2:$A$1277,$A9,'Teacher Salary Data'!$C$2:$C$1277,"Master's",'Teacher Salary Data'!$D$2:$D$1277,0) | H9: =SUMIFS('Teacher Salary Data'!$E$2:$E$1277,'Teacher Salary Data'!$A$2:$A$1277,$A9,'Teacher Salary Data'!$C$2:$C$1277,"Master's",'Teacher Salary Data'!$D$2:$D$1277,5) | I9: =SUMIFS('Teacher Salary Data'!$E$2:$E$1277,'Teacher Salary Data'!$A$2:$A$1277,$A9,'Teacher Salary Data'!$C$2:$C$1277,"Master's",'Teacher Salary Data'!$D$2:$D$1277,10) | J9: =AVERAGE(D9,G9) | K9: =AVERAGE(F9,I9) | L9: =IFERROR((K9-J9)/J9,0) | M9: =G9-D9 | N9: =IFERROR(INDEX('Median Home and Rent Prices'!$D$2:$D$58,MATCH($A9,'Median Home and Rent Prices'!$A$2:$A$58,0)),0) | O9: =IFERROR(INDEX('Median Home and Rent Prices'!$E$2:$E$58,MATCH($A9,'Median Home and Rent Prices'!$A$2:$A$58,0)),0) | P9: =IFERROR(INDEX('School District Profiles'!$H$2:$H$58,MATCH($A9,'School District Profiles'!$A$2:$A$58,0)),0) | Q9: =IFERROR(INDEX('School District Profiles'!$I$2:$I$58,MATCH($A9,'School District Profiles'!$A$2:$A$58,0)),0) | R9: =IFERROR(MAX(0,MIN(100,(K9-50000)/(110000-50000)*100)),0) | S9: =IFERROR(MAX(0,MIN(100,L9/0.6*100)),0) | T9: =IFERROR(MAX(0,MIN(100,M9/15000*100)),0) | U9: =IFERROR(0.45*R9+0.4*S9+0.15*T9,0) | V9: =IFERROR(0.4*MAX(0,MIN(100,(((J9/12)/O9)-2)/(4-2)*100))+0.35*MAX(0,MIN(100,(8-(N9/K9))/(8-3)*100))+0.25*AB9,0) | W9: =IFERROR(MAX(0,MIN(100,(25-P9)/(25-12)*100)),0) | X9: =IFERROR(MAX(0,MIN(100,(AD9-1)/(3-1)*100))*IF(OR($A9="North Clackamas School District",$A9="Provo City School District"),0.6,1),0) | Y9: =IFERROR(MAX(0,MIN(100,(1-((IFERROR(INDEX('School District Profiles'!$D$2:$D$58,MATCH($A9,'School District Profiles'!$A$2:$A$58,0)),0)/100)^2+(IFERROR(INDEX('School District Profiles'!$E$2:$E$58,MATCH($A9,'School District Profiles'!$A$2:$A$58,0)),0)/100)^2+(IFERROR(INDEX('School District Profiles'!$F$2:$F$58,MATCH($A9,'School District Profiles'!$A$2:$A$58,0)),0)/100)^2+(IFERROR(INDEX('School District Profiles'!$G$2:$G$58,MATCH($A9,'School District Profiles'!$A$2:$A$58,0)),0)/100)^2+(AC9/100)^2))/0.8*100)),0) | Z9: =IFERROR(AF9*AG9,0) | AA9: =IFERROR(INDEX('Median Home and Rent Prices'!$F$2:$F$58,MATCH($A9,'Median Home and Rent Prices'!$A$2:$A$58,0)),0) | AB9: =IFERROR(MAX(0,MIN(100,(800-AA9)/(800-150)*100)),0) | AC9: =IFERROR(INDEX('School District Profiles'!$J$2:$J$58,MATCH($A9,'School District Profiles'!$A$2:$A$58,0)),0) | AD9: =IFERROR(Q9*20/O9,0) | AE9: =IFERROR(IF(AG9>=1,100,IF(AG9>=0.95,75,IF(AG9>=0.9,60,IF(AG9>=0.85,40,IF(AG9>=0.8,25,0))))),0) | AF9: =IFERROR(0.4*U9+0.3*V9+0.1*W9+0.1*X9+0.1*Y9,0) | AG9: 0.85 | AH9: 15% employment-stability penalty due to announced job reductions and districtwide budget-cut plan.
A10: Chicago Public Schools | B10: =IFERROR(INDEX('School District Profiles'!$B$2:$B$58,MATCH($A10,'School District Profiles'!$A$2:$A$58,0)),"") | C10: =IFERROR(INDEX('School District Profiles'!$C$2:$C$58,MATCH($A10,'School District Profiles'!$A$2:$A$58,0)),"") | D10: =SUMIFS('Teacher Salary Data'!$E$2:$E$1277,'Teacher Salary Data'!$A$2:$A$1277,$A10,'Teacher Salary Data'!$C$2:$C$1277,"Bachelor's",'Teacher Salary Data'!$D$2:$D$1277,0) | E10: =SUMIFS('Teacher Salary Data'!$E$2:$E$1277,'Teacher Salary Data'!$A$2:$A$1277,$A10,'Teacher Salary Data'!$C$2:$C$1277,"Bachelor's",'Teacher Salary Data'!$D$2:$D$1277,5) | F10: =SUMIFS('Teacher Salary Data'!$E$2:$E$1277,'Teacher Salary Data'!$A$2:$A$1277,$A10,'Teacher Salary Data'!$C$2:$C$1277,"Bachelor's",'Teacher Salary Data'!$D$2:$D$1277,10) | G10: =SUMIFS('Teacher Salary Data'!$E$2:$E$1277,'Teacher Salary Data'!$A$2:$A$1277,$A10,'Teacher Salary Data'!$C$2:$C$1277,"Master's",'Teacher Salary Data'!$D$2:$D$1277,0) | H10: =SUMIFS('Teacher Salary Data'!$E$2:$E$1277,'Teacher Salary Data'!$A$2:$A$1277,$A10,'Teacher Salary Data'!$C$2:$C$1277,"Master's",'Teacher Salary Data'!$D$2:$D$1277,5) | I10: =SUMIFS('Teacher Salary Data'!$E$2:$E$1277,'Teacher Salary Data'!$A$2:$A$1277,$A10,'Teacher Salary Data'!$C$2:$C$1277,"Master's",'Teacher Salary Data'!$D$2:$D$1277,10) | J10: =AVERAGE(D10,G10) | K10: =AVERAGE(F10,I10) | L10: =IFERROR((K10-J10)/J10,0) | M10: =G10-D10 | N10: =IFERROR(INDEX('Median Home and Rent Prices'!$D$2:$D$58,MATCH($A10,'Median Home and Rent Prices'!$A$2:$A$58,0)),0) | O10: =IFERROR(INDEX('Median Home and Rent Prices'!$E$2:$E$58,MATCH($A10,'Median Home and Rent Prices'!$A$2:$A$58,0)),0) | P10: =IFERROR(INDEX('School District Profiles'!$H$2:$H$58,MATCH($A10,'School District Profiles'!$A$2:$A$58,0)),0) | Q10: =IFERROR(INDEX('School District Profiles'!$I$2:$I$58,MATCH($A10,'School District Profiles'!$A$2:$A$58,0)),0) | R10: =IFERROR(MAX(0,MIN(100,(K10-50000)/(110000-50000)*100)),0) | S10: =IFERROR(MAX(0,MIN(100,L10/0.6*100)),0) | T10: =IFERROR(MAX(0,MIN(100,M10/15000*100)),0) | U10: =IFERROR(0.45*R10+0.4*S10+0.15*T10,0) | V10: =IFERROR(0.4*MAX(0,MIN(100,(((J10/12)/O10)-2)/(4-2)*100))+0.35*MAX(0,MIN(100,(8-(N10/K10))/(8-3)*100))+0.25*AB10,0) | W10: =IFERROR(MAX(0,MIN(100,(25-P10)/(25-12)*100)),0) | X10: =IFERROR(MAX(0,MIN(100,(AD10-1)/(3-1)*100))*IF(OR($A10="North Clackamas School District",$A10="Provo City School District"),0.6,1),0) | Y10: =IFERROR(MAX(0,MIN(100,(1-((IFERROR(INDEX('School District Profiles'!$D$2:$D$58,MATCH($A10,'School District Profiles'!$A$2:$A$58,0)),0)/100)^2+(IFERROR(INDEX('School District Profiles'!$E$2:$E$58,MATCH($A10,'School District Profiles'!$A$2:$A$58,0)),0)/100)^2+(IFERROR(INDEX('School District Profiles'!$F$2:$F$58,MATCH($A10,'School District Profiles'!$A$2:$A$58,0)),0)/100)^2+(IFERROR(INDEX('School District Profiles'!$G$2:$G$58,MATCH($A10,'School District Profiles'!$A$2:$A$58,0)),0)/100)^2+(AC10/100)^2))/0.8*100)),0) | Z10: =IFERROR(AF10*AG10,0) | AA10: =IFERROR(INDEX('Median Home and Rent Prices'!$F$2:$F$58,MATCH($A10,'Median Home and Rent Prices'!$A$2:$A$58,0)),0) | AB10: =IFERROR(MAX(0,MIN(100,(800-AA10)/(800-150)*100)),0) | AC10: =IFERROR(INDEX('School District Profiles'!$J$2:$J$58,MATCH($A10,'School District Profiles'!$A$2:$A$58,0)),0) | AD10: =IFERROR(Q10*20/O10,0) | AE10: =IFERROR(IF(AG10>=1,100,IF(AG10>=0.95,75,IF(AG10>=0.9,60,IF(AG10>=0.85,40,IF(AG10>=0.8,25,0))))),0) | AF10: =IFERROR(0.4*U10+0.3*V10+0.1*W10+0.1*X10+0.1*Y10,0) | AG10: 0.85 | AH10: 15% employment-stability penalty due to structural deficit and reported teacher-position reductions / higher class-size planning.
A11: Cobb County School District | B11: =IFERROR(INDEX('School District Profiles'!$B$2:$B$58,MATCH($A11,'School District Profiles'!$A$2:$A$58,0)),"") | C11: =IFERROR(INDEX('School District Profiles'!$C$2:$C$58,MATCH($A11,'School District Profiles'!$A$2:$A$58,0)),"") | D11: =SUMIFS('Teacher Salary Data'!$E$2:$E$1277,'Teacher Salary Data'!$A$2:$A$1277,$A11,'Teacher Salary Data'!$C$2:$C$1277,"Bachelor's",'Teacher Salary Data'!$D$2:$D$1277,0) | E11: =SUMIFS('Teacher Salary Data'!$E$2:$E$1277,'Teacher Salary Data'!$A$2:$A$1277,$A11,'Teacher Salary Data'!$C$2:$C$1277,"Bachelor's",'Teacher Salary Data'!$D$2:$D$1277,5) | F11: =SUMIFS('Teacher Salary Data'!$E$2:$E$1277,'Teacher Salary Data'!$A$2:$A$1277,$A11,'Teacher Salary Data'!$C$2:$C$1277,"Bachelor's",'Teacher Salary Data'!$D$2:$D$1277,10) | G11: =SUMIFS('Teacher Salary Data'!$E$2:$E$1277,'Teacher Salary Data'!$A$2:$A$1277,$A11,'Teacher Salary Data'!$C$2:$C$1277,"Master's",'Teacher Salary Data'!$D$2:$D$1277,0) | H11: =SUMIFS('Teacher Salary Data'!$E$2:$E$1277,'Teacher Salary Data'!$A$2:$A$1277,$A11,'Teacher Salary Data'!$C$2:$C$1277,"Master's",'Teacher Salary Data'!$D$2:$D$1277,5) | I11: =SUMIFS('Teacher Salary Data'!$E$2:$E$1277,'Teacher Salary Data'!$A$2:$A$1277,$A11,'Teacher Salary Data'!$C$2:$C$1277,"Master's",'Teacher Salary Data'!$D$2:$D$1277,10) | J11: =AVERAGE(D11,G11) | K11: =AVERAGE(F11,I11) | L11: =IFERROR((K11-J11)/J11,0) | M11: =G11-D11 | N11: =IFERROR(INDEX('Median Home and Rent Prices'!$D$2:$D$58,MATCH($A11,'Median Home and Rent Prices'!$A$2:$A$58,0)),0) | O11: =IFERROR(INDEX('Median Home and Rent Prices'!$E$2:$E$58,MATCH($A11,'Median Home and Rent Prices'!$A$2:$A$58,0)),0) | P11: =IFERROR(INDEX('School District Profiles'!$H$2:$H$58,MATCH($A11,'School District Profiles'!$A$2:$A$58,0)),0) | Q11: =IFERROR(INDEX('School District Profiles'!$I$2:$I$58,MATCH($A11,'School District Profiles'!$A$2:$A$58,0)),0) | R11: =IFERROR(MAX(0,MIN(100,(K11-50000)/(110000-50000)*100)),0) | S11: =IFERROR(MAX(0,MIN(100,L11/0.6*100)),0) | T11: =IFERROR(MAX(0,MIN(100,M11/15000*100)),0) | U11: =IFERROR(0.45*R11+0.4*S11+0.15*T11,0) | V11: =IFERROR(0.4*MAX(0,MIN(100,(((J11/12)/O11)-2)/(4-2)*100))+0.35*MAX(0,MIN(100,(8-(N11/K11))/(8-3)*100))+0.25*AB11,0) | W11: =IFERROR(MAX(0,MIN(100,(25-P11)/(25-12)*100)),0) | X11: =IFERROR(MAX(0,MIN(100,(AD11-1)/(3-1)*100))*IF(OR($A11="North Clackamas School District",$A11="Provo City School District"),0.6,1),0) | Y11: =IFERROR(MAX(0,MIN(100,(1-((IFERROR(INDEX('School District Profiles'!$D$2:$D$58,MATCH($A11,'School District Profiles'!$A$2:$A$58,0)),0)/100)^2+(IFERROR(INDEX('School District Profiles'!$E$2:$E$58,MATCH($A11,'School District Profiles'!$A$2:$A$58,0)),0)/100)^2+(IFERROR(INDEX('School District Profiles'!$F$2:$F$58,MATCH($A11,'School District Profiles'!$A$2:$A$58,0)),0)/100)^2+(IFERROR(INDEX('School District Profiles'!$G$2:$G$58,MATCH($A11,'School District Profiles'!$A$2:$A$58,0)),0)/100)^2+(AC11/100)^2))/0.8*100)),0) | Z11: =IFERROR(AF11*AG11,0) | AA11: =IFERROR(INDEX('Median Home and Rent Prices'!$F$2:$F$58,MATCH($A11,'Median Home and Rent Prices'!$A$2:$A$58,0)),0) | AB11: =IFERROR(MAX(0,MIN(100,(800-AA11)/(800-150)*100)),0) | AC11: =IFERROR(INDEX('School District Profiles'!$J$2:$J$58,MATCH($A11,'School District Profiles'!$A$2:$A$58,0)),0) | AD11: =IFERROR(Q11*20/O11,0) | AE11: =IFERROR(IF(AG11>=1,100,IF(AG11>=0.95,75,IF(AG11>=0.9,60,IF(AG11>=0.85,40,IF(AG11>=0.8,25,0))))),0) | AF11: =IFERROR(0.4*U11+0.3*V11+0.1*W11+0.1*X11+0.1*Y11,0) | AG11: 1 | AH11: No penalty applied. Cobb's FY2027 public budget messaging states no teacher layoffs and emphasizes classroom stability; local reporting notes staffing reductions are handled through attrition/reassignment rather than layoffs.
